Workbook

Sheet  

Sheet Pokyny k vyplnění
B2: POKYNY K VYPLNĚNÍ FORMULÁŘE
B4: Seznam použitých zkratek: GDPR - NAŘÍZENÍ EVROPSKÉHO PRLAMENTU A RADY (EU) 2016/679 ze dne 27. dubna 2016 o ochraně fyzických osob v souvislosti se zpracováním osobních údajů a o volném pohybu těchto údajů a o zrušení směrnice 95/46/ES (obecné nařízení o ochraně osobních údajů) OOÚ - ochrana osobních údajů OÚ - osobní údaj ZOOÚ - zákon č. 101/2000 Sb., o ochraně osobních údajů a o změně některých zákonů
B6: List FORMULÁŘ nevyplňujte! Zkopírujte jej, kopii nazvěte číslem zpracování, které bude uvedeno v buňce C3, a poté jej vyplňte. Takto postupujte u každého nového formuláře pro další zpracování.
B8: List "ÚVOD"
B9: buňka | C9: název | D9: pokyny k vyplnění polí
B10: C5 | C10: správce: | D10: Jméno správce, kterým je vaše organizace.
B11: D6 | C11: se sídlem: | D11: Adresa sídla podle příslušného zápisu v obchodním rejstříku nebo obdobné evidenci.
B12: D7 | C12: IČ: | D12: IČ podle příslušného rejstříku.
B13: D8 | C13: jednající: | D13: Jméno a příjmení jednající osoby podle příslušného zápisu v bochodním rejtříku nebo obdobné evidenci.
B14: D9 | C14: odpovědná osoba pro oblast ochrany osobních údajů: | D14: Jméno a příjmení odpovědné osoby za celou oblast ochrany osobních údajů u správce.
B15: D11 | C15: e-mail | D15: Pracovní e-mail odpovědné osoby.
B16: D12 | C16: telefon | D16: Pracovní telefonní číslo odpovědné osoby.
B17: D13 | C17: jmenovaný pověřenec pro ochranu osobních údajů: | D17: Jméno a příjmení pověřence, pokud je jmenován.
B18: D15 | C18: e-mail | D18: Pracovní e-mail pověřence, pokud je jmenován.
B19: D16 | C19: telefon | D19: Pracovní telefonní číslo pověřence, pokud je jmenován.
B21: List "FORMULÁŘ"
B22: buňka | C22: název | D22: pokyny k vyplnění polí
B23: C2 | C23: Název zpracování: | D23: Uveďte název zpracování, kterým je nejlépe vystižena agenda, v níž jsou osobní údaje zpracovány (Personální a mzdová evidence, Evidence držitelů vstupních karet, Kamerový systém, Dodavatelské a odběratelské smlouvy, ....). Název zpracování se bude používat v navazujících dokumentech.
B24: C3 | C24: Číslo zpracování: | D24: Každé zpracování označte jedinečným označením (forma číslování není stanovena). Číslo pak použijte v názvu daného listu, např. "35", "RSV-02" apod.
B25: C4 | C25: Organizační jednotka: | D25: Organizační jednotkou je myšlena organizační součást správce, který zpracování provádí (např. ekonomický odbor, personální oddělení apod.). Nejsou-li organizační součásti zavedeny, údaj se nevyplňuje.
B26: C5 | C26: Číslo organizační jednotky: | D26: Vyplňte pouze v případě, že organizační součást má přidělené vlastní číslo, pod kterým je v příslušných interních aktech řízení uváděna.
B27: C6 | C27: Odpovědná osoba: | D27: Odpovědná osoba za danou oblast zpracování (uveďte titul, jméno, příjmení, pracovní pozici). Uvedená osoba by měla být současně respondentem tohoto check listu. Nedoporučujeme, aby byla jmenována více, než jedna odpovědná osoba za jedno identifikované zpracování.
B28: C7 | C28: - e-mail: | D28: Uveďte pracovní e-mail odpovědné osoby.
B29: C8 | C29: - telefon: | D29: Uveďte pracovní telefonní číslo odpovědné osoby.
B30: C9 | C30: Oprávnění zaměstnanci: | D30: Uveďte výčet pracovních pozic spolu se zařazením do organizačních jednotek, které jsou oprávněny zpracovávat předmětné OÚ. Výčet těchto pozic má vliv na pozdější stanovení bezpečnostních opatření, zejména pak v oblasti fyzické bezpečnosti a bezpečnosti IT. Nezapomínejte na osoby, které mají oprávnění na základě svých specifických pracovních povinností, např. generální ředitel, právník, interní auditoři apod., vč. osob, které zajišťují případnou zastupitelnost.
B31: C10 | C31: Příjemci OÚ: | D31: Vyplňte puze v případě, že příjemcem osobních údajů budou osoby mimo subjekt údajů a správce, vč. jeho zaměstnanců. Tyto osoby pak specifikujte (např. komerční pojišťovny, ČSSZ, zdravotní pojišťovny, smluvní partneři atd.) Neuvádějte subjekty uvedené ve větě druhé citované definice. „příjemcem“ fyzická nebo právnická osoba, orgán veřejné moci, agentura nebo jiný subjekt, kterým jsou osobní údaje poskytnuty, ať už se jedná o třetí stranu, či nikoli. Avšak orgány veřejné moci, které mohou získávat osobní údaje v rámci zvláštního šetření v souladu s právem členského státu, se za příjemce nepovažují; zpracování těchto osobních údajů těmito orgány veřejné moci musí být v souladu s použitelnými pravidly ochrany údajů pro dané účely zpracování (čl. 4 odst. 9 GDPR)
B33: C12 | C33: Počet subjektů údajů: | D33: Uveďte počet subjektů údajů (zaokrouhleně), k nimž se OÚ zpracovávají, např. "20", "300", "12.000". Nezapomeňte na osoby, jejichž údaje aktivně nevyužíváte, přesto jejich OÚ archivujete, např. v případě personální evidence. Je-li současný počet zaměstnanců 400, společnost působí na trhu 18 let a roční fluktuace činí cca 40 osob, pak celkový počet subjektů údajů bude 400 + (18 * 40) = 1.120
B34: C13 | C34: Další místa zpracování: | D34: Uveďte všechna místa zpracování, pokud jsou odlišná od sídla uvedeného na listu "Úvod". Uveďte přesné adresy a stát, pokud není místo v České republice.
... B56: C35 | C56: Počet zpracovatelů: | D56: Uveďte počet zpracovatelů, kteří se podílení na zpracování, které je předmětem tohoto check listu. Pokud je zpracovatelů více, než pět, údaje vyplňte na samostatné příloze.
C58: ZPRACOVATEL 1
B59: C37 | C59: Firma (název) zpracovatele: | D59: Použijte údaje z obchodního nebo jiného rejstříku.
B60: C38 | C60: se sídlem: | D60: Použijte údaje z obchodního nebo jiného rejstříku.
B61: C39 | C61: IČ: | D61: Použijte údaje z obchodního nebo jiného rejstříku.
B62: C40 | C62: odpovědná osoba: | D62: Uveďte osobu odpovědnou za zpracování osobních údajů (např. dle smlouvy o zpracování osobních údajů).
B63: C41 | C63: e-mail: | D63: Uveďte e-mail odpovědné osoby.
B64: C42 | C64: telefon: | D64: Uveďte telefonní číslo odpovědné osoby.
B65: C43 | C65: Smlouva o zpracování OÚ: | D65: Použijte jednu z nabízených možností.
B66: C44 | C66: Právní předpis: | D66: Uveďte ustanovení příslušného právního předpisu.
C68: ZPRACOVATEL 2
B69: C47 | C69: Firma (název) zpracovatele: | D69: Použijte údaje z obchodního nebo jiného rejstříku.
...

Sheet Úvod
C3: Identifikace zpracování osobních údajů
B5: správce: | C5: xxx
C6: se sídlem: | D6: adresa
C7: IČ:
C8: jednající: | D8: jméno a příjmení
C9: odpovědná osoba pro oblast ochrany osobních údajů:
D10: titul, jméno a příjmení
C11: e-mail
C12: telefon
C13: jmenovaný pověřenec pro ochranu osobních údajů:
D14: titul, jméno a příjmení
C15: e-mail
C16: telefon

Sheet Vzor 1
B2: Název zpracování: | C2: Záznamy ze CCTV
B3: Číslo zpracování: | C3: A001
B4: Organizační jednotka: | C4: IT oddělení
B5: Číslo organizační jednotky:
B6: Odpovědná osoba: | C6: Ing. Miroslav Švanda
B7: - e-mail: | C7: m.svanda@zk.cz
B8: - telefon: | C8: +420 720 258 698
B9: Oprávnění zaměstnanci: | C9: vedoucí IT oddělení, security manager
B10: Příjemci OÚ: | C10: komerční pojišťovny
B12: Počet subjektů údajů: | C12: 1000
B13: Další místa zpracování: | C13: nejsou
B14: Zdroj OÚ: | C14: kamerový systém
B15: Způsob zpracování: | C15: automatizované
B16: Přeshraniční zpracování: | C16: NE
B17: Druh OÚ: | C17: audiovizuální záznam osob
B18: - zákonnost zpracování: | C18: f
B19: Zvláštní kategorie OÚ: | C19: NE
B20: =IF(C19="ANO"," - jejich druh:","")
B21: =IF(C19="ANO"," - zákonnost zpracování:","")
B22: OÚ o trestních věcech: | C22: NE
B23: Účel zpracování: | C23: ochrana života a zdraví osob, ochrana majetku správce a osob vstupujících do monitorovaného prostoru, ochrana informací
B24: Kategorie subjektů údajů: | C24: osoby vstupující do monitorovaného prostoru
B25: Předávání do zahraničí: | C25: NE
B26: Doba uložení OÚ: | C26: 30 dní
B27: - důvod: | C27: Dokumentování příp. protiprávních jednání, vč. latentní kriminality, s ohledem na možnost včas pořídit kopii záznamu pro předání příslušným orgánům jako důkaz pro příslušné řízení. Kratší doba je vyloučena s ohledem na bezpečnostní situaci v lokalitě, kde je CCTV umístěno a s ohledem na časté požadavky Policie ČR o předání záznamů ze CCTV starších 3 týdnů.
B28: Místa uložení osobních údajů: | C28: Kopie záznamů v trezoru kanceláře č. 209 (vedoucího IT).
B29: Profilování: | C29: NE
B30: Posouzení vlivu: | C30: NE
B31: - provedení:
B32: Společný správce: | C32: NE
B34: Zpracovatel: | C34: ANO
B35: =IF(C34="ANO","Počet zpracovatelů:"," ") -> Počet zpracovatelů: | C35: 1
C36: 3
B37: =IF(C35>0,"ZPRACOVATEL 1"," ") -> ZPRACOVATEL 1
B38: =IF(C35>0,"Firma (název) zpracovatele:"," ") -> Firma (název) zpracovatele: | C38: První hlídací s.r.o.
B39: =IF(C35>0,"se sídlem:"," ") -> se sídlem: | C39: Modřanská 354/18, 100 00 Praha 10
B40: =IF(C35>0,"IČ:"," ") -> IČ: | C40: 25469874
B41: =IF(C35>0,"odpovědná osoba:"," ") -> odpovědná osoba: | C41: Mgr. Jaroslav Obezřetný
B42: =IF(C35>0,"e-mail:"," ") -> e-mail: | C42: jobezretny@prvnihlidaci.com
B43: =IF(C35>0,"telefon:"," ") -> telefon: | C43: +420 603 258 699
...

Sheet Vzor 2
B2: Název zpracování: | C2: Personální evidence
B3: Číslo zpracování: | C3: P001
B4: Organizační jednotka: | C4: personální oddělení
B5: Číslo organizační jednotky:
B6: Odpovědná osoba: | C6: Ing. Marie Pracovitá
B7: - e-mail: | C7: m.pracovita@zk.cz
B8: - telefon: | C8: +420 720 147 147
B9: Oprávnění zaměstnanci: | C9: vedení společnosti, personální ředitel, zaměstnanci personálního oddělení, vedoucí zaměstnanci
B10: Příjemci OÚ: | C10: zdravotní pojišťovny, ČSSZ, úřad práce, …..
B12: Počet subjektů údajů: | C12: 4000
B13: Další místa zpracování: | C13: nejsou
B14: Zdroj OÚ: | C14: od subjektu údajů
B15: Způsob zpracování: | C15: automatizované + neautomatizované (v listinné podobě)
B16: Přeshraniční zpracování: | C16: NE
B17: Druh OÚ: | C17: titul, jméno, příjmení, datum narození, rodné číslo, trvalé bydliště, doručovací adresa, ……………………., fotografie zaměstnance
B18: - zákonnost zpracování: | C18: a - fotografie zaměstnance, c - dle pracovněprávních předpisů, f - fotografie zaměstnance
B19: Zvláštní kategorie OÚ: | C19: NE
B20: =IF(C19="ANO"," - jejich druh:","")
B21: =IF(C19="ANO"," - zákonnost zpracování:","")
B22: OÚ o trestních věcech: | C22: NE
B23: Účel zpracování: | C23: Plnění povinností podle pracovněprávních předpisů. Fotografie zaměstnance pro její zveřejnění na webových stránkách společnosti a pro vystavení přístupových karet zaměstnanců.
B24: Kategorie subjektů údajů: | C24: zaměstnanci
B25: Předávání do zahraničí: | C25: NE
B26: Doba uložení OÚ: | C26: Podle požadavků příslušných právních předpisů, fotografie xx dnů od data ukončení pracovního nebo obdobného poměru.
B27: - důvod: | C27: Plnění zákonných povinností a vnitřních předpisů (režimová opatření ke vstupu zaměstnanců do areálu společnosti a pohyb v něm), propagace společnosti po dobu trvání pracovního poměru zaměstnance.
B28: Místa uložení osobních údajů: | C28: Archiv (dv. č. 350), kanceláře personálního oddělení (dv. č. 222 - 225).
B29: Profilování: | C29: NE
B30: Posouzení vlivu: | C30: NEVÍM
B31: - provedení: | C31: NEVÍM
B32: Společný správce: | C32: NE
B34: Zpracovatel: | C34: NE
B35: =IF(C34="ANO","Počet zpracovatelů:"," ")
C36: 3
B37: =IF(C35>0,"ZPRACOVATEL 1"," ")
B38: =IF(C35>0,"Firma (název) zpracovatele:"," ") | C38: =IF(B38=" "," ","")
B39: =IF(C35>0,"se sídlem:"," ") | C39: =IF(B39=" "," ","")
B40: =IF(C35>0,"IČ:"," ") | C40: =IF(B40=" "," ","")
B41: =IF(C35>0,"odpovědná osoba:"," ") | C41: =IF(B41=" "," ","")
B42: =IF(C35>0,"e-mail:"," ") | C42: =IF(B42=" "," ","")
B43: =IF(C35>0,"telefon:"," ") | C43: =IF(B43=" "," ","")
...

Sheet FORMULÁŘ (2)
B2: Název zpracování: | C2: Záznamy ze CCTV
B3: Číslo zpracování: | C3: IT 1
B4: Organizační jednotka: | C4: IT oddělení
B5: Číslo organizační jednotky: | C5: 9
B6: Odpovědná osoba:
B7: - e-mail:
B8: - telefon:
B9: Oprávnění zaměstnanci: | C9: IT oddělení
B10: Příjemci OÚ: | C10: NE
B12: Počet subjektů údajů: | C12: 230
B13: Další místa zpracování:
B14: Zdroj OÚ: | C14: Kamerový systém
B15: Způsob zpracování: | C15: automatizované
B16: Přeshraniční zpracování: | C16: NE
B17: Druh OÚ: | C17: vizuální záznam osob
B18: - zákonnost zpracování: | C18: 1f
B19: Zvláštní kategorie OÚ: | C19: NE
B20: =IF(C19="ANO"," - jejich druh:","")
B21: =IF(C19="ANO"," - zákonnost zpracování:","")
B22: OÚ o trestních věcech: | C22: NE
B23: Účel zpracování: | C23: ochrana osob a majetku ve firemním areálu
B24: Kategorie subjektů údajů: | C24: Zaměstnanci, zákazníci, návštěvníci
B25: Předávání do zahraničí: | C25: NE
B26: Doba uložení OÚ: | C26: 20 dní
B27: - důvod: | C27: Dokumentování případných protiprávních jednání. Ochrana zaměstnanců a majetku.
B28: Místa uložení osobních údajů:
B29: Profilování: | C29: NE
B30: Posouzení vlivu: | C30: NE
B31: - provedení: | C31: NE
B32: Společný správce: | C32: NE
B34: Zpracovatel: | C34: NE
B35: =IF(C34="ANO","Počet zpracovatelů:"," ")
C36: 3
B37: =IF(C35>0,"ZPRACOVATEL 1"," ")
B38: =IF(C35>0,"Firma (název) zpracovatele:"," ") | C38: =IF(B38=" "," ","")
B39: =IF(C35>0,"se sídlem:"," ") | C39: =IF(B39=" "," ","")
B40: =IF(C35>0,"IČ:"," ") | C40: =IF(B40=" "," ","")
B41: =IF(C35>0,"odpovědná osoba:"," ") | C41: =IF(B41=" "," ","")
B42: =IF(C35>0,"e-mail:"," ") | C42: =IF(B42=" "," ","")
B43: =IF(C35>0,"telefon:"," ") | C43: =IF(B43=" "," ","")
...

Sheet FORMULÁŘ
B2: Název zpracování: | C2: Zálohy serverů a databází
B3: Číslo zpracování: | C3: IT 2
B4: Organizační jednotka: | C4: IT oddělení
B5: Číslo organizační jednotky:
B6: Odpovědná osoba:
B7: - e-mail:
B8: - telefon:
B9: Oprávnění zaměstnanci: | C9: IT oddělení
B10: Příjemci OÚ: | C10: NE
B12: Počet subjektů údajů: | C12: 50000
B13: Další místa zpracování:
B14: Zdroj OÚ: | C14: od subjektu údajů
B15: Způsob zpracování: | C15: Automatizované
B16: Přeshraniční zpracování: | C16: NE
B17: Druh OÚ: | C17: ?
B18: - zákonnost zpracování: | C18: 1f
B19: Zvláštní kategorie OÚ: | C19: NE
B20: =IF(C19="ANO"," - jejich druh:","")
B21: =IF(C19="ANO"," - zákonnost zpracování:","")
B22: OÚ o trestních věcech: | C22: NE
B23: Účel zpracování: | C23: Ochrana dat, prevence proti ztrátě
B24: Kategorie subjektů údajů: | C24: od subjektu údajů
B25: Předávání do zahraničí: | C25: NE
B26: Doba uložení OÚ: | C26: 1 měsíc?
B27: - důvod: | C27: zálohování dat
B28: Místa uložení osobních údajů:
B29: Profilování: | C29: NE
B30: Posouzení vlivu: | C30: NE
B31: - provedení:
B32: Společný správce: | C32: NE
B34: Zpracovatel: | C34: ANO
B35: =IF(C34="ANO","Počet zpracovatelů:"," ") -> Počet zpracovatelů: | C35: 1
C36: 3
B37: =IF(C35>0,"ZPRACOVATEL 1"," ") -> ZPRACOVATEL 1
B38: =IF(C35>0,"Firma (název) zpracovatele:"," ") -> Firma (název) zpracovatele:
B39: =IF(C35>0,"se sídlem:"," ") -> se sídlem:
B40: =IF(C35>0,"IČ:"," ") -> IČ:
B41: =IF(C35>0,"odpovědná osoba:"," ") -> odpovědná osoba:
B42: =IF(C35>0,"e-mail:"," ") -> e-mail: | C42: =IF(B42=" "," ","")
B43: =IF(C35>0,"telefon:"," ") -> telefon: | C43: =IF(B43=" "," ","")
...

Sheet Data
A1: správce: | B1: ANO | C1: NENÍ PÍSEMNĚ UZAVŘENA | E1: automatizované | F1: od subjektu údajů | G1: NE | H1: NE
A2: zpracovatele: | B2: NE | C2: UZAVŘENA podle § 6 ZOOÚ | D2: 1 | E2: neautomatizované (v listinné podobě) | F2: veřejně dostupné zdroje | G2: ANO - EU | H2: ANO - podle písm. a)
B3: NEVÍM | C3: UZAVŘENA podle § 6 ZOOÚ a revidována podle čl. 28 odst. 3 GDPR | D3: 2 | E3: automatizované + neautomatizované (v listinné podobě) | F3: jiné zdroje | G3: ANO - EU i třetí země nebo mezinárodní organizace | H3: ANO - podle písm. b)
C4: UZAVŘENA podle čl. 28 odst. 3 GDPR | D4: 3 | G4: ANO - třetí země nebo mezinárodní organizace | H4: ANO - podle písm. a) a b)
C5: ZMOCNĚNÍ VYPLÝVÁ Z PRÁVNÍHO PŘEDPISU | D5: 4 | H5: NEVÍM
C6: NEVÍM | D6: 5
D7: .
